Workbook

Sheet CARTAS CONVITE
A1: STATUS | B1: Tempo Pendente | C1: TEMPO P/ FECHAMENTO | D1: Seq. | E1: DATA ENVIO COMPRAS | F1: Nº CARTA CONVITE | G1: PACOTES | H1: ÁREA | I1: RESPONSÁVEL | J1: TIPO DE MANUTENÇÃO | K1: COMPRADOR | L1: LISTA | M1: PRAZO FINALIZAR | N1: EQUALIZAÇÃO | O1: PROPOSTA TÉCNICA RESPONDIDA? | P1: PENDENTE | Q1: DATA DO PEDIDO | R1: NR. PEDIDO | S1: VALOR | T1: OBSERVAÇÕES | U1: PROPOSTAS RECEBIDAS | V1: FORNECEDOR A | W1: FORNECEDOR B | X1: FORNECEDOR C | Y1: FORNECEDOR D | Z1: FORNECEDOR E | AA1: FORNECEDOR F | AB1: FORNECEDOR G | AC1: OBS | AD1: EMPRESA NEGOCIADA | AE1: SC - Solicitação
A2: =IF(Tabela2[[#This Row],[DATA DO PEDIDO]]<>"", "Finalizado", IF(Tabela2[[#This Row],[DATA ENVIO COMPRAS]]="", "Aguardando Coordenador", IF(Tabela2[[#This Row],[EQUALIZAÇÃO]]="", "Aguardando Fornecedores", "Aguardando Pedido" ) ) ) -> Aguardando Fornecedores | B2: =IF(Tabela2[[#This Row],[DATA DO PEDIDO]]<>"","Finalizado",IF(Tabela2[[#This Row],[DATA ENVIO COMPRAS]]="","",_xlfn.DAYS(TODAY(),Tabela2[[#This Row],[DATA ENVIO COMPRAS]])&IF(_xlfn.DAYS(TODAY(),Tabela2[[#This Row],[DATA ENVIO COMPRAS]])>1," Dias"," Dia"))) -> 11 Dias | C2: =IF(Tabela2[[#This Row],[DATA DO PEDIDO]]<>"",Tabela2[[#This Row],[DATA DO PEDIDO]]-Tabela2[[#This Row],[DATA ENVIO COMPRAS]],"") | D2: =IF(D1="Seq.",1,D1+1) -> 1 | E2: 46151 | F2: 001-0/26 | G2: PENEIRA ROT. DECANTADOR | H2: TRATAMENTO DE CALDO | I2: Rodrigo Zavatti | J2: Manut. Externa | K2: Jhonatan | L2: Críticos | M2: =IF(E2="","",WORKDAY(E2,22)) -> 46182 | P2: Compras | U2: =COUNTA(Tabela2[[#This Row],[FORNECEDOR A]:[FORNECEDOR G]]) -> 0
A3: =IF(Tabela2[[#This Row],[DATA DO PEDIDO]]<>"", "Finalizado", IF(Tabela2[[#This Row],[DATA ENVIO COMPRAS]]="", "Aguardando Coordenador", IF(Tabela2[[#This Row],[EQUALIZAÇÃO]]="", "Aguardando Fornecedores", "Aguardando Pedido" ) ) ) -> Aguardando Pedido | B3: =IF(Tabela2[[#This Row],[DATA DO PEDIDO]]<>"","Finalizado",IF(Tabela2[[#This Row],[DATA ENVIO COMPRAS]]="","",_xlfn.DAYS(TODAY(),Tabela2[[#This Row],[DATA ENVIO COMPRAS]])&IF(_xlfn.DAYS(TODAY(),Tabela2[[#This Row],[DATA ENVIO COMPRAS]])>1," Dias"," Dia"))) -> 22 Dias | C3: =IF(Tabela2[[#This Row],[DATA DO PEDIDO]]<>"",Tabela2[[#This Row],[DATA DO PEDIDO]]-Tabela2[[#This Row],[DATA ENVIO COMPRAS]],"") | D3: =IF(D2="Seq.",1,D2+1) -> 2 | E3: 46140 | F3: 002-0/26 | G3: REFORMA TALISCAS MESA MA | H3: MOENDA A | I3: Rodrigo Zavatti | J3: Manut. Externa | K3: Jhonatan | L3: Críticos | M3: =IF(E3="","",WORKDAY(E3,22)) -> 46170 | N3: 46155 | O3: Sim | P3: Compras | U3: =COUNTA(Tabela2[[#This Row],[FORNECEDOR A]:[FORNECEDOR G]]) -> 0 | AD3: HD | AE3: 628388
A4: =IF(Tabela2[[#This Row],[DATA DO PEDIDO]]<>"", "Finalizado", IF(Tabela2[[#This Row],[DATA ENVIO COMPRAS]]="", "Aguardando Coordenador", IF(Tabela2[[#This Row],[EQUALIZAÇÃO]]="", "Aguardando Fornecedores", "Aguardando Pedido" ) ) ) -> Aguardando Coordenador | B4: =IF(Tabela2[[#This Row],[DATA DO PEDIDO]]<>"","Finalizado",IF(Tabela2[[#This Row],[DATA ENVIO COMPRAS]]="","",_xlfn.DAYS(TODAY(),Tabela2[[#This Row],[DATA ENVIO COMPRAS]])&IF(_xlfn.DAYS(TODAY(),Tabela2[[#This Row],[DATA ENVIO COMPRAS]])>1," Dias"," Dia"))) | C4: =IF(Tabela2[[#This Row],[DATA DO PEDIDO]]<>"",Tabela2[[#This Row],[DATA DO PEDIDO]]-Tabela2[[#This Row],[DATA ENVIO COMPRAS]],"") | D4: =IF(D3="Seq.",1,D3+1) -> 3 | F4: 003-0/26 | G4: PERITAGEM ELETROIMA | H4: MOENDA A | I4: Rodrigo Zavatti | J4: Manut. Externa | K4: Jhonatan | L4: Críticos | M4: =IF(E4="","",WORKDAY(E4,22)) | P4: Coordenador | U4: =COUNTA(Tabela2[[#This Row],[FORNECEDOR A]:[FORNECEDOR G]]) -> 0
A5: =IF(Tabela2[[#This Row],[DATA DO PEDIDO]]<>"", "Finalizado", IF(Tabela2[[#This Row],[DATA ENVIO COMPRAS]]="", "Aguardando Coordenador", IF(Tabela2[[#This Row],[EQUALIZAÇÃO]]="", "Aguardando Fornecedores", "Aguardando Pedido" ) ) ) -> Aguardando Fornecedores | B5: =IF(Tabela2[[#This Row],[DATA DO PEDIDO]]<>"","Finalizado",IF(Tabela2[[#This Row],[DATA ENVIO COMPRAS]]="","",_xlfn.DAYS(TODAY(),Tabela2[[#This Row],[DATA ENVIO COMPRAS]])&IF(_xlfn.DAYS(TODAY(),Tabela2[[#This Row],[DATA ENVIO COMPRAS]])>1," Dias"," Dia"))) -> 22 Dias | C5: =IF(Tabela2[[#This Row],[DATA DO PEDIDO]]<>"",Tabela2[[#This Row],[DATA DO PEDIDO]]-Tabela2[[#This Row],[DATA ENVIO COMPRAS]],"") | D5: =IF(D4="Seq.",1,D4+1) -> 4 | E5: 46140 | F5: 004-0/26 | G5: REFORMA ESTEIRA TT01 - TT02 | H5: CALDEIRAS | I5: Rodrigo Zavatti | J5: Manut. Externa | K5: Jhonatan | L5: Críticos | M5: =IF(E5="","",WORKDAY(E5,22)) -> 46170 | P5: Compras | U5: =COUNTA(Tabela2[[#This Row],[FORNECEDOR A]:[FORNECEDOR G]]) -> 0
A6: =IF(Tabela2[[#This Row],[DATA DO PEDIDO]]<>"", "Finalizado", IF(Tabela2[[#This Row],[DATA ENVIO COMPRAS]]="", "Aguardando Coordenador", IF(Tabela2[[#This Row],[EQUALIZAÇÃO]]="", "Aguardando Fornecedores", "Aguardando Pedido" ) ) ) -> Aguardando Fornecedores | B6: =IF(Tabela2[[#This Row],[DATA DO PEDIDO]]<>"","Finalizado",IF(Tabela2[[#This Row],[DATA ENVIO COMPRAS]]="","",_xlfn.DAYS(TODAY(),Tabela2[[#This Row],[DATA ENVIO COMPRAS]])&IF(_xlfn.DAYS(TODAY(),Tabela2[[#This Row],[DATA ENVIO COMPRAS]])>1," Dias"," Dia"))) -> 22 Dias | C6: =IF(Tabela2[[#This Row],[DATA DO PEDIDO]]<>"",Tabela2[[#This Row],[DATA DO PEDIDO]]-Tabela2[[#This Row],[DATA ENVIO COMPRAS]],"") | D6: =IF(D5="Seq.",1,D5+1) -> 5 | E6: 46140 | F6: 005-0/26 | G6: REFORMA CORRENTES MESA MA ESTEIRAS METALICAS MA E MB | H6: MOENDAS | I6: Rodrigo Zavatti | J6: Manut. Externa | K6: Jhonatan | L6: Críticos | M6: =IF(E6="","",WORKDAY(E6,22)) -> 46170 | P6: Compras | U6: =COUNTA(Tabela2[[#This Row],[FORNECEDOR A]:[FORNECEDOR G]]) -> 0
A7: =IF(Tabela2[[#This Row],[DATA DO PEDIDO]]<>"", "Finalizado", IF(Tabela2[[#This Row],[DATA ENVIO COMPRAS]]="", "Aguardando Coordenador", IF(Tabela2[[#This Row],[EQUALIZAÇÃO]]="", "Aguardando Fornecedores", "Aguardando Pedido" ) ) ) -> Aguardando Fornecedores | B7: =IF(Tabela2[[#This Row],[DATA DO PEDIDO]]<>"","Finalizado",IF(Tabela2[[#This Row],[DATA ENVIO COMPRAS]]="","",_xlfn.DAYS(TODAY(),Tabela2[[#This Row],[DATA ENVIO COMPRAS]])&IF(_xlfn.DAYS(TODAY(),Tabela2[[#This Row],[DATA ENVIO COMPRAS]])>1," Dias"," Dia"))) -> 22 Dias | C7: =IF(Tabela2[[#This Row],[DATA DO PEDIDO]]<>"",Tabela2[[#This Row],[DATA DO PEDIDO]]-Tabela2[[#This Row],[DATA ENVIO COMPRAS]],"") | D7: =IF(D6="Seq.",1,D6+1) -> 6 | E7: 46140 | F7: 006-0/26 | G7: REFORMA TALISCAS ESTEIRAS METALICAS MA E MB | H7: MOENDAS | I7: Rodrigo Zavatti | J7: Manut. Externa | K7: Jhonatan | L7: Críticos | M7: =IF(E7="","",WORKDAY(E7,22)) -> 46170 | P7: Compras | U7: =COUNTA(Tabela2[[#This Row],[FORNECEDOR A]:[FORNECEDOR G]]) -> 0
A8: =IF(Tabela2[[#This Row],[DATA DO PEDIDO]]<>"", "Finalizado", IF(Tabela2[[#This Row],[DATA ENVIO COMPRAS]]="", "Aguardando Coordenador", IF(Tabela2[[#This Row],[EQUALIZAÇÃO]]="", "Aguardando Fornecedores", "Aguardando Pedido" ) ) ) -> Aguardando Fornecedores | B8: =IF(Tabela2[[#This Row],[DATA DO PEDIDO]]<>"","Finalizado",IF(Tabela2[[#This Row],[DATA ENVIO COMPRAS]]="","",_xlfn.DAYS(TODAY(),Tabela2[[#This Row],[DATA ENVIO COMPRAS]])&IF(_xlfn.DAYS(TODAY(),Tabela2[[#This Row],[DATA ENVIO COMPRAS]])>1," Dias"," Dia"))) -> 16 Dias | C8: =IF(Tabela2[[#This Row],[DATA DO PEDIDO]]<>"",Tabela2[[#This Row],[DATA DO PEDIDO]]-Tabela2[[#This Row],[DATA ENVIO COMPRAS]],"") | D8: =IF(D7="Seq.",1,D7+1) -> 7 | E8: 46146 | F8: 007-0/26 | G8: REFORMA SIST. HID. MOENDAS | H8: MOENDAS | I8: Rodrigo Zavatti | J8: Manut. Externa | K8: Jhonatan | L8: Críticos | M8: =IF(E8="","",WORKDAY(E8,22)) -> 46176 | P8: Compras | U8: =COUNTA(Tabela2[[#This Row],[FORNECEDOR A]:[FORNECEDOR G]]) -> 0

Sheet GRAFICOS
H2: CARTAS: | I2: 88
H3: FINALIZADAS | I3: 85
H4: AGUARDANDO RETORNO | I4: 3
H17: CARTAS: | I17: 9
H18: FINALIZADAS | I18: 9
H19: AGUARDANDO RETORNO | I19: 0

Sheet BASE 2024
B4: STATUS | C4: Tempo Pendente | D4: Seq. | E4: PACOTES | F4: CRÍTICIDADE | G4: RESPONSÁVEL | H4: EMPRESAS PARTICIPANTES | I4: TOTAL | J4: ENVIO COMPRAS | K4: PRAZO RETORNO | L4: PROPOSTAS RECEBIDAS | M4: ENVIO EQUALIZAÇÃO | N4: FORNECEDOR A | O4: FORNECEDOR B | P4: FORNECEDOR C | Q4: FORNECEDOR D | R4: FORNECEDOR E | S4: FORNECEDOR F | T4: FORNECEDOR G | U4: OBSERVAÇÕES4 | V4: EMPRESA NEGOCIADA | W4: SC | X4: INCLUSO NA PLANILHA?
A5: OK | B5: =IF($X5<>"","Finalizado",IF($O5<>"","Comprador Negociando",IF($M5>=TODAY(),"Aguardando Retorno Fornecedores","Prazo de Retorno Vencido"))) -> Finalizado | C5: =IF(B5="Finalizado","Ok",IF(IF(M5="",_xlfn.DAYS(TODAY(),J5),_xlfn.DAYS(TODAY(),M5))>1,IF(M5="",_xlfn.DAYS(TODAY(),J5),_xlfn.DAYS(TODAY(),M5))&" Dias",IF(M5="",_xlfn.DAYS(TODAY(),J5),_xlfn.DAYS(TODAY(),M5))&" Dia")) -> Ok | D5: 1 | E5: CORRENTES ARRASTE | F5: Alta | H5: Ello/General Chains/ Linksteel/Pro-link/Tetracon | I5: 5 | J5: 45491 | K5: 45506 | L5: =COUNTA([1]Equalizações!S2:Y2) -> 1 | M5: 45512 | N5: PROLINK | O5: GENERAL CHAINS | P5: ELLO CORRENTS | Q5: LINKSTEEL | R5: TETRACOM | V5: TETRACOM/ LINKSTEEL | W5: 561148/561372/561150/561375 561198/561199/561207/561216 561219/561220/561222/561254 | X5: SIM
A6: OK | B6: =IF($X6<>"","Finalizado",IF($O6<>"","Comprador Negociando",IF($M6>=TODAY(),"Aguardando Retorno Fornecedores","Prazo de Retorno Vencido"))) -> Finalizado | C6: =IF(B6="Finalizado","Ok",IF(IF(M6="",_xlfn.DAYS(TODAY(),J6),_xlfn.DAYS(TODAY(),M6))>1,IF(M6="",_xlfn.DAYS(TODAY(),J6),_xlfn.DAYS(TODAY(),M6))&" Dias",IF(M6="",_xlfn.DAYS(TODAY(),J6),_xlfn.DAYS(TODAY(),M6))&" Dia")) -> Ok | D6: 2 | E6: MANUTENÇÃO EM DESFIBRADOR | F6: Alta | H6: Dedini/Dourados/ Magister/Mefsa/Moreno/ Simisa/Theodor | I6: 7 | J6: 45495 | K6: 45512 | L6: =COUNTA([1]Equalizações!S5:Y5) -> 7 | M6: 45533 | N6: DEDINI (DECLINOU) | O6: DOURADOS (DECLINOU) | P6: MEFSA | Q6: THEODOR | R6: MORENO (DECLINOU) | S6: MAGISTER | T6: SIMISA RESPONDEU P/ COMPRAS | V6: MAGISTER | W6: 562351/565991 | X6: SIM
A7: OK | B7: =IF($X7<>"","Finalizado",IF($O7<>"","Comprador Negociando",IF($M7>=TODAY(),"Aguardando Retorno Fornecedores","Prazo de Retorno Vencido"))) -> Finalizado | C7: =IF(B7="Finalizado","Ok",IF(IF(M7="",_xlfn.DAYS(TODAY(),J7),_xlfn.DAYS(TODAY(),M7))>1,IF(M7="",_xlfn.DAYS(TODAY(),J7),_xlfn.DAYS(TODAY(),M7))&" Dias",IF(M7="",_xlfn.DAYS(TODAY(),J7),_xlfn.DAYS(TODAY(),M7))&" Dia")) -> Ok | D7: 3 | E7: MANUTENÇÃO DO SISTEMA HIDRAULICO MOENDA A e B | F7: Média | H7: Desidério/RRV/Renova/ Fatto/Oriente | I7: 5 | J7: 45496 | K7: 45514 | L7: =COUNTA([1]Equalizações!S3:Y3) -> 7 | M7: 45525 | N7: DESIDÉRIO | O7: ORIENTE | P7: RENOVA | Q7: RRV | R7: FATTO | V7: ORIENT | W7: 562078/562076 | X7: SIM
A8: OK | B8: =IF($X8<>"","Finalizado",IF($O8<>"","Comprador Negociando",IF($M8>=TODAY(),"Aguardando Retorno Fornecedores","Prazo de Retorno Vencido"))) -> Finalizado | C8: =IF(B8="Finalizado","Ok",IF(IF(M8="",_xlfn.DAYS(TODAY(),J8),_xlfn.DAYS(TODAY(),M8))>1,IF(M8="",_xlfn.DAYS(TODAY(),J8),_xlfn.DAYS(TODAY(),M8))&" Dias",IF(M8="",_xlfn.DAYS(TODAY(),J8),_xlfn.DAYS(TODAY(),M8))&" Dia")) -> Ok | D8: 5 | E8: MANUTENÇÃO CENTRIFUGAS KONT | F8: Baixa | H8: Ad Service/Ferramaq/Renova/ TJR/Vetek/Vibromaq/Vibrotec | I8: 7 | J8: 45498 | K8: 45517 | L8: =COUNTA([1]Equalizações!S9:Y9) -> 6 | M8: 45553 | N8: RENOVA | O8: FERREMAQ | P8: ADSERVICE (DECLINOU) | Q8: VIBROTEC | R8: TJR (NÃO RESPONDEU) | S8: Vetek (NÃO RESPONDEU) | T8: Vibromaq (NÃO RESPONDEU) | V8: RENOVA | W8: 563060/563061/563062/563063/563064 | X8: SIM
A9: CONTRATO | B9: =IF($X9<>"","Finalizado",IF($O9<>"","Comprador Negociando",IF($M9>=TODAY(),"Aguardando Retorno Fornecedores","Prazo de Retorno Vencido"))) -> Finalizado | C9: =IF(B9="Finalizado","Ok",IF(IF(M9="",_xlfn.DAYS(TODAY(),J9),_xlfn.DAYS(TODAY(),M9))>1,IF(M9="",_xlfn.DAYS(TODAY(),J9),_xlfn.DAYS(TODAY(),M9))&" Dias",IF(M9="",_xlfn.DAYS(TODAY(),J9),_xlfn.DAYS(TODAY(),M9))&" Dia")) -> Ok | D9: 7 | E9: BOROSCOPIA | F9: Baixa | H9: Contec/Gmtec/Sew/SB END/Welding/Wortice | I9: 6 | J9: 45502 | K9: 45517 | L9: =COUNTA([1]Equalizações!S10:Y10) -> 6 | M9: 45553 | N9: GMTEC | O9: SEW* | P9: SB END | Q9: WORTICE | R9: Welding (NÃO RESPONDEU) | S9: Contec (NÃO RESPONDEU) | V9: SEW | W9: 563074/563075 | X9: SIM
B10: =IF($X10<>"","Finalizado",IF($O10<>"","Comprador Negociando",IF($M10>=TODAY(),"Aguardando Retorno Fornecedores","Prazo de Retorno Vencido"))) -> Finalizado | C10: =IF(B10="Finalizado","Ok",IF(IF(M10="",_xlfn.DAYS(TODAY(),J10),_xlfn.DAYS(TODAY(),M10))>1,IF(M10="",_xlfn.DAYS(TODAY(),J10),_xlfn.DAYS(TODAY(),M10))&" Dias",IF(M10="",_xlfn.DAYS(TODAY(),J10),_xlfn.DAYS(TODAY(),M10))&" Dia")) -> Ok | D10: 8 | E10: FILTRAGEM DE OLÉO | F10: Baixa | H10: Maxlubri/Purilub/TratLUB | I10: 3 | J10: 45504 | K10: 45520 | L10: =COUNTA([1]Equalizações!S4:Y4) -> 7 | M10: 45526 | N10: MAXLUBRI | O10: TRATLUB | P10: PURILUB | V10: MAX LUBRI | W10: 561678/561681/561682/ 1047/1048/1114/561709 | X10: SIM
A11: OK | B11: =IF($X11<>"","Finalizado",IF($O11<>"","Comprador Negociando",IF($M11>=TODAY(),"Aguardando Retorno Fornecedores","Prazo de Retorno Vencido"))) -> Finalizado | C11: =IF(B11="Finalizado","Ok",IF(IF(M11="",_xlfn.DAYS(TODAY(),J11),_xlfn.DAYS(TODAY(),M11))>1,IF(M11="",_xlfn.DAYS(TODAY(),J11),_xlfn.DAYS(TODAY(),M11))&" Dias",IF(M11="",_xlfn.DAYS(TODAY(),J11),_xlfn.DAYS(TODAY(),M11))&" Dia")) -> Ok | D11: 9 | E11: PACOTE MOENDAS A e B | F11: Alta | H11: CCM/DEDINI/MEFSA/ MORENO/SIMISA/POWER MOENDAS | I11: 6 | J11: 45505 | K11: 45524 | L11: =COUNTA([1]Equalizações!S6:Y6) -> 5 | M11: 45533 | N11: MEFSA | O11: MORENO (DECLINOU) | P11: CCM | Q11: DEDINI | R11: SIMISA RESPONDEU COMPRAS | S11: POWER MOENDAS (CERIBELI Ñ QHR) | V11: CCM | W11: 561968/561990/562025/ 562044/562035/562036/ 566023 | X11: SIM
A12: OK | B12: =IF($X12<>"","Finalizado",IF($O12<>"","Comprador Negociando",IF($M12>=TODAY(),"Aguardando Retorno Fornecedores","Prazo de Retorno Vencido"))) -> Finalizado | C12: =IF(B12="Finalizado","Ok",IF(IF(M12="",_xlfn.DAYS(TODAY(),J12),_xlfn.DAYS(TODAY(),M12))>1,IF(M12="",_xlfn.DAYS(TODAY(),J12),_xlfn.DAYS(TODAY(),M12))&" Dias",IF(M12="",_xlfn.DAYS(TODAY(),J12),_xlfn.DAYS(TODAY(),M12))&" Dia")) -> Ok | D12: 14 | E12: INSPEÇÃO CORRENTES ARRASTE | F12: Alta | H12: SB END/WELDING/SOLIEND/ QUALYSERVICE | I12: 4 | J12: 45534 | K12: 45545 | L12: =COUNTA([1]Equalizações!S8:Y8) -> 7 | M12: 45547 | N12: SOLIEND | O12: SB END | P12: QUALYSERVICE | Q12: WELDING | V12: WELDING | W12: 562125/564307 | X12: SIM
A13: OK | B13: =IF($X13<>"","Finalizado",IF($O13<>"","Comprador Negociando",IF($M13>=TODAY(),"Aguardando Retorno Fornecedores","Prazo de Retorno Vencido"))) -> Finalizado | C13: =IF(B13="Finalizado","Ok",IF(IF(M13="",_xlfn.DAYS(TODAY(),J13),_xlfn.DAYS(TODAY(),M13))>1,IF(M13="",_xlfn.DAYS(TODAY(),J13),_xlfn.DAYS(TODAY(),M13))&" Dias",IF(M13="",_xlfn.DAYS(TODAY(),J13),_xlfn.DAYS(TODAY(),M13))&" Dia")) -> Ok | D13: 12 | E13: CONFECÇÃO EIXO E ROTOR PARA EXAUSTOR (SPOT) | F13: Média | H13: ASTE/AERO/VIBROTEC | I13: 3 | J13: 45537 | K13: 45545 | L13: =COUNTA([1]Equalizações!S13:Y13) -> 4 | M13: 45581 | N13: AERO | O13: VIBROTEC | P13: ASTE | V13: VIBROTEC | W13: 562506 (Luiza) | X13: SIM
B14: =IF($X14<>"","Finalizado",IF($O14<>"","Comprador Negociando",IF($M14>=TODAY(),"Aguardando Retorno Fornecedores","Prazo de Retorno Vencido"))) -> Finalizado | C14: =IF(B14="Finalizado","Ok",IF(IF(M14="",_xlfn.DAYS(TODAY(),J14),_xlfn.DAYS(TODAY(),M14))>1,IF(M14="",_xlfn.DAYS(TODAY(),J14),_xlfn.DAYS(TODAY(),M14))&" Dias",IF(M14="",_xlfn.DAYS(TODAY(),J14),_xlfn.DAYS(TODAY(),M14))&" Dia")) -> Ok | D14: 10 | E14: Pacote Inspeção Vasos de Pressão NR13 | F14: Baixa | H14: ENGETEX/ENGEVESSEL/ENGINEERS/JRE INSPEÇÃO | I14: 4 | J14: 45531 | K14: 45547 | L14: =COUNTA([1]Equalizações!S7:Y7) -> 7 | M14: 45546 | N14: ENGINEERS | O14: ENGEVESSEL | P14: JRE INSPEÇÃO | Q14: ENGETEX | V14: ENGETEX | W14: 563067 | X14: SIM
A15: OK | B15: =IF($X15<>"","Finalizado",IF($O15<>"","Comprador Negociando",IF($M15>=TODAY(),"Aguardando Retorno Fornecedores","Prazo de Retorno Vencido"))) -> Finalizado | C15: =IF(B15="Finalizado","Ok",IF(IF(M15="",_xlfn.DAYS(TODAY(),J15),_xlfn.DAYS(TODAY(),M15))>1,IF(M15="",_xlfn.DAYS(TODAY(),J15),_xlfn.DAYS(TODAY(),M15))&" Dias",IF(M15="",_xlfn.DAYS(TODAY(),J15),_xlfn.DAYS(TODAY(),M15))&" Dia")) -> Ok | D15: 11 | E15: TORRES DE RESFRIAMENTO | F15: Alta | H15: COBERMIL/RB/VETTOR | I15: 3 | J15: 45539 | K15: 45548 | L15: =COUNTA([1]Equalizações!S12:Y12) -> 7 | M15: 45577 | N15: RB SERVIÇOS | O15: COBERMIL | P15: VETTOR | V15: RB SERVIÇOS | W15: 1054/1039/563668/563669/563670/563671/563672/563673/563674/563675/563677/563678/563679/563680/563681/563682/563683/563684/563687 | X15: SIM
A16: OK | B16: =IF($X16<>"","Finalizado",IF($O16<>"","Comprador Negociando",IF($M16>=TODAY(),"Aguardando Retorno Fornecedores","Prazo de Retorno Vencido"))) -> Finalizado | C16: =IF(B16="Finalizado","Ok",IF(IF(M16="",_xlfn.DAYS(TODAY(),J16),_xlfn.DAYS(TODAY(),M16))>1,IF(M16="",_xlfn.DAYS(TODAY(),J16),_xlfn.DAYS(TODAY(),M16))&" Dias",IF(M16="",_xlfn.DAYS(TODAY(),J16),_xlfn.DAYS(TODAY(),M16))&" Dia")) -> Ok | D16: 15 | E16: MANUTENÇÃO NAS TURBINAS Á VAPOR | F16: Alta | H16: TGM/Wortice | I16: 2 | J16: 45546 | K16: 45553 | L16: =COUNTA([1]Equalizações!S11:Y11) -> 7 | M16: 45561 | N16: WORTICE | O16: TGM | V16: WORTICE | W16: 1051/1052/1119 | X16: SIM
A17: OK | B17: =IF($X17<>"","Finalizado",IF($O17<>"","Comprador Negociando",IF($M17>=TODAY(),"Aguardando Retorno Fornecedores","Prazo de Retorno Vencido"))) -> Finalizado | C17: =IF(B17="Finalizado","Ok",IF(IF(M17="",_xlfn.DAYS(TODAY(),J17),_xlfn.DAYS(TODAY(),M17))>1,IF(M17="",_xlfn.DAYS(TODAY(),J17),_xlfn.DAYS(TODAY(),M17))&" Dias",IF(M17="",_xlfn.DAYS(TODAY(),J17),_xlfn.DAYS(TODAY(),M17))&" Dia")) -> Ok | D17: 13 | E17: INSPEÇÃO EXTRAÇÃO (MOENDAS) | F17: Alta | H17: SB End/Welding/Soliend/ QualyService/JRE Inspeções | I17: 5 | J17: 45552 | K17: 45562 | L17: =COUNTA([1]Equalizações!S14:Y14) -> 5 | M17: 45581 | N17: SOLIEND | O17: WELDING | P17: QUALYSERVICE | Q17: SB END (NÃO ENVIOU) | R17: JRE (NÃO ENVIOU) | V17: WELDING | W17: 563742/563745 | X17: SIM
A18: OK | B18: =IF($X18<>"","Finalizado",IF($O18<>"","Comprador Negociando",IF($M18>=TODAY(),"Aguardando Retorno Fornecedores","Prazo de Retorno Vencido"))) -> Comprador Negociando | C18: =IF(B18="Finalizado","Ok",IF(IF(M18="",_xlfn.DAYS(TODAY(),J18),_xlfn.DAYS(TODAY(),M18))>1,IF(M18="",_xlfn.DAYS(TODAY(),J18),_xlfn.DAYS(TODAY(),M18))&" Dias",IF(M18="",_xlfn.DAYS(TODAY(),J18),_xlfn.DAYS(TODAY(),M18))&" Dia")) -> 581 Dias | D18: 18 | E18: SOPRADORES DE FULIGEM | F18: Média | H18: Process-Prother/Heron/Promoen/ Clyde/Lsi/ | I18: 5 | J18: 45558 | K18: 45569 | L18: =COUNTA([1]Equalizações!S19:Y19) -> 5 | M18: 45581 | N18: CLYDE (DECLINOU) | O18: HEROM | P18: PROMOEN | Q18: PROTHER | R18: LSI (NÃO ENVIOU) | V18: PROTHER | W18: 565.141/565.142
A19: OK | B19: =IF($X19<>"","Finalizado",IF($O19<>"","Comprador Negociando",IF($M19>=TODAY(),"Aguardando Retorno Fornecedores","Prazo de Retorno Vencido"))) -> Finalizado | C19: =IF(B19="Finalizado","Ok",IF(IF(M19="",_xlfn.DAYS(TODAY(),J19),_xlfn.DAYS(TODAY(),M19))>1,IF(M19="",_xlfn.DAYS(TODAY(),J19),_xlfn.DAYS(TODAY(),M19))&" Dias",IF(M19="",_xlfn.DAYS(TODAY(),J19),_xlfn.DAYS(TODAY(),M19))&" Dia")) -> Ok | D19: 19 | E19: VISORES DE NIVEL | F19: Média | H19: Pmatec/Tecviso/Aurea/ Tecnoval/Visortech | I19: 5 | J19: 45558 | K19: 45574 | L19: =COUNTA([1]Equalizações!S15:Y15) -> 5 | M19: 45581 | N19: TECVISO | O19: VISORTECH | P19: PMATEC | Q19: TECNOVAL | R19: AUREA (NÃO ENVIOU) | V19: PMATEC | W19: 563432/563435/563436 | X19: SIM
A20: OK | B20: =IF($X20<>"","Finalizado",IF($O20<>"","Comprador Negociando",IF($M20>=TODAY(),"Aguardando Retorno Fornecedores","Prazo de Retorno Vencido"))) -> Finalizado | C20: =IF(B20="Finalizado","Ok",IF(IF(M20="",_xlfn.DAYS(TODAY(),J20),_xlfn.DAYS(TODAY(),M20))>1,IF(M20="",_xlfn.DAYS(TODAY(),J20),_xlfn.DAYS(TODAY(),M20))&" Dias",IF(M20="",_xlfn.DAYS(TODAY(),J20),_xlfn.DAYS(TODAY(),M20))&" Dia")) -> Ok | D20: 22 | E20: PERITAGEM GERADORES | F20: Alta | H20: WEG/Data Engenharia/Buscarioli/Harpia/Ecovis | I20: 5 | J20: 45562 | K20: 45576 | L20: =COUNTA([1]Equalizações!S16:Y16) -> 7 | M20: 45581 | N20: WEG | O20: HARPIA | P20: Data Engenharia | Q20: Buscarioli (não enviou) | R20: Ecovis (Fora Prazo) | V20: Data Engenharia | W20: 564223/1057/1058/1124 | X20: SIM
B21: =IF($X21<>"","Finalizado",IF($O21<>"","Comprador Negociando",IF($M21>=TODAY(),"Aguardando Retorno Fornecedores","Prazo de Retorno Vencido"))) -> Finalizado | C21: =IF(B21="Finalizado","Ok",IF(IF(M21="",_xlfn.DAYS(TODAY(),J21),_xlfn.DAYS(TODAY(),M21))>1,IF(M21="",_xlfn.DAYS(TODAY(),J21),_xlfn.DAYS(TODAY(),M21))&" Dias",IF(M21="",_xlfn.DAYS(TODAY(),J21),_xlfn.DAYS(TODAY(),M21))&" Dia")) -> Ok | D21: 24 | E21: PACOTE VALVULAS DE CALDO | F21: Média | G21: Edjaldo Dias Batista | H21: TJA/APM/Tecnoval | I21: 3 | J21: 45566 | K21: 45576 | L21: =COUNTA([1]Equalizações!S17:Y17) -> 7 | M21: 45590 | N21: TJA | O21: APM | P21: Tecnoval | U21: Eliminou as negociações através formulário Ceribeli | V21: TJA | W21: 562427/562356 | X21: SIM
B22: =IF($X22<>"","Finalizado",IF($O22<>"","Comprador Negociando",IF($M22>=TODAY(),"Aguardando Retorno Fornecedores","Prazo de Retorno Vencido"))) -> Finalizado | C22: =IF(B22="Finalizado","Ok",IF(IF(M22="",_xlfn.DAYS(TODAY(),J22),_xlfn.DAYS(TODAY(),M22))>1,IF(M22="",_xlfn.DAYS(TODAY(),J22),_xlfn.DAYS(TODAY(),M22))&" Dias",IF(M22="",_xlfn.DAYS(TODAY(),J22),_xlfn.DAYS(TODAY(),M22))&" Dia")) -> Ok | D22: 16 | E22: MANUTENÇÃO LINHA DE PRESSÃO CALDEIRA 01 - RV01 | F22: Alta | G22: Eduardo Rogerio Maggio | H22: MR MONTAGENS/ORCA/ MONINSC/GLM/FRS/ZAP/G. LIMA | I22: 7 | J22: 45575 | K22: 45580 | L22: =COUNTA([1]Equalizações!S20:Y20) -> 5 | M22: 45588 | N22: ORCA | O22: MONINSC | P22: frs (declinou) | Q22: GLM | R22: MR MONTAGENS (Não resp.) | S22: ZAP (AG ORÇ) | T22: GRUPO LIMA (AG excel) | V22: ORCA | W22: 564300 | X22: SIM
B23: =IF($X23<>"","Finalizado",IF($O23<>"","Comprador Negociando",IF($M23>=TODAY(),"Aguardando Retorno Fornecedores","Prazo de Retorno Vencido"))) -> Finalizado | C23: =IF(B23="Finalizado","Ok",IF(IF(M23="",_xlfn.DAYS(TODAY(),J23),_xlfn.DAYS(TODAY(),M23))>1,IF(M23="",_xlfn.DAYS(TODAY(),J23),_xlfn.DAYS(TODAY(),M23))&" Dias",IF(M23="",_xlfn.DAYS(TODAY(),J23),_xlfn.DAYS(TODAY(),M23))&" Dia")) -> Ok | D23: 26 | E23: PACOTE TRANSMISSORES (in loco) | F23: Baixa | G23: Valtenir José de Brito | H23: ENGINSTREL/GMG/GSA/ACCI/E.R.FLOW | I23: 5 | J23: 45573 | K23: 45580 | L23: =COUNTA([1]Equalizações!S22:Y22) -> 7 | M23: 45590 | N23: ACCI | O23: GMG | P23: Engistrel | Q23: GSA | R23: ER FLOW | V23: ER FLOW | W23: 564565/564569/564574/564576/564577/564593/564594 | X23: SIM
A24: N/A | B24: =IF($X24<>"","Finalizado",IF($O24<>"","Comprador Negociando",IF($M24>=TODAY(),"Aguardando Retorno Fornecedores","Prazo de Retorno Vencido"))) -> Finalizado | C24: =IF(B24="Finalizado","Ok",IF(IF(M24="",_xlfn.DAYS(TODAY(),J24),_xlfn.DAYS(TODAY(),M24))>1,IF(M24="",_xlfn.DAYS(TODAY(),J24),_xlfn.DAYS(TODAY(),M24))&" Dias",IF(M24="",_xlfn.DAYS(TODAY(),J24),_xlfn.DAYS(TODAY(),M24))&" Dia")) -> Ok | D24: 17 | E24: CALDEIRARIA MOENDAS A E B | F24: Alta | H24: DAR AGRO/ZAP/NS/MFC/DRW | I24: 5 | J24: 45558 | K24: 45583 | L24: =COUNTA([1]Equalizações!S25:Y25) -> 5 | M24: 45603 | N24: NS | O24: DAR AGRO | P24: ZAP | Q24: MFC | R24: DRW (NÃO RESPONDEU) | V24: ZAP | W24: 564799/564804/564805/564806/564807 | X24: SIM
A25: OK | B25: =IF($X25<>"","Finalizado",IF($O25<>"","Comprador Negociando",IF($M25>=TODAY(),"Aguardando Retorno Fornecedores","Prazo de Retorno Vencido"))) -> Finalizado | C25: =IF(B25="Finalizado","Ok",IF(IF(M25="",_xlfn.DAYS(TODAY(),J25),_xlfn.DAYS(TODAY(),M25))>1,IF(M25="",_xlfn.DAYS(TODAY(),J25),_xlfn.DAYS(TODAY(),M25))&" Dias",IF(M25="",_xlfn.DAYS(TODAY(),J25),_xlfn.DAYS(TODAY(),M25))&" Dia")) -> Ok | D25: 23 | E25: CALDEIRARIA GERAL DO PROCESSO | F25: Alta | G25: Renan Araújo Junqueira Bueno | H25: DAR AGRO/ZAP/NS/FRS/MFC/ GTS/SMI | I25: 7 | J25: 45565 | K25: 45583 | L25: =COUNTA([1]Equalizações!S26:Y26) -> 6 | M25: 45603 | N25: SMI | O25: ZAP | P25: DAR AGRO | Q25: NS | R25: DRW | S25: MFC (DECLINOU) | T25: GTS (DECLINOU) | V25: DAR AGRO / SMI /SB END / BC MAIS / LL MONTAGEM / GRUPO GAMMA | W25: 564.613/564.616/564.618/564.619/564.620/564.621/564.624/564.625/564.625/564.626/564.626/564.627/564.628/564.629/564.630/564.631/564.631/564.631/564.632/564.633/564.634/564.635/564.636/564.637/564.638/564.639/564.641/564.642/564.643/564.644/564.645/564.646/564.647/564.648/564.650/564.651/564.653/564.654/564.655/564.656/564.657/564.664/564.665/564.666/564.667/564.668/564.669/564.670/564.671/564.673/564.674/564.675/564.676/564.677/564.678/564.679/564.681/564.682/564.684/564.685/564.686/564.697/564.698/564.699/564.700/564.701/564.702/564.703/564.704/564.705/564.706/564.707/564.708/564.709/564.711/564.712/564.713/564.716/564.719/564.721/564.722/564.723/564.842/564.843/564.844/564.845/564.846/564.847 | X25: SIM
B26: =IF($X26<>"","Finalizado",IF($O26<>"","Comprador Negociando",IF($M26>=TODAY(),"Aguardando Retorno Fornecedores","Prazo de Retorno Vencido"))) -> Finalizado | C26: =IF(B26="Finalizado","Ok",IF(IF(M26="",_xlfn.DAYS(TODAY(),J26),_xlfn.DAYS(TODAY(),M26))>1,IF(M26="",_xlfn.DAYS(TODAY(),J26),_xlfn.DAYS(TODAY(),M26))&" Dias",IF(M26="",_xlfn.DAYS(TODAY(),J26),_xlfn.DAYS(TODAY(),M26))&" Dia")) -> Ok | D26: 20 | E26: PACOTE CALDEIRARIA SIDERURGICA CALDEIRA 01 | F26: Alta | G26: Eduardo Rogerio Maggio | H26: DAR AGRO/ZAP/NS/FRS/MFC/ GTS/DRW/SMI | I26: 7 | J26: 45576 | K26: 45583 | L26: =COUNTA([1]Equalizações!S27:Y27) -> 7 | M26: 45603 | N26: SMI | O26: NS | P26: ZAP | Q26: DAR AGRO | R26: GAMMA | S26: BC MAIS (FALTA EQUALIZAR) | T26: DRW/GTS/MFC (DECLINOU) | V26: GAMMA/SMI/DAR AGRO | W26: 564773/564774/564775/564776/564960/564961/564962/564963/564964/564965/564966/564969/564970/564971/564972/564974/564975/564976/564979/564980/564982/564983 | X26: SIM
A27: OK | B27: =IF($X27<>"","Finalizado",IF($O27<>"","Comprador Negociando",IF($M27>=TODAY(),"Aguardando Retorno Fornecedores","Prazo de Retorno Vencido"))) -> Finalizado | C27: =IF(B27="Finalizado","Ok",IF(IF(M27="",_xlfn.DAYS(TODAY(),J27),_xlfn.DAYS(TODAY(),M27))>1,IF(M27="",_xlfn.DAYS(TODAY(),J27),_xlfn.DAYS(TODAY(),M27))&" Dias",IF(M27="",_xlfn.DAYS(TODAY(),J27),_xlfn.DAYS(TODAY(),M27))&" Dia")) -> Ok | D27: 25 | E27: Confecção de Tanques | F27: Baixa | G27: Renan Araújo Junqueira Bueno | H27: DAR AGRO/ZAP/NS/DRW/MFC/ GTS/SMI | I27: 7 | J27: 45580 | K27: 45583 | L27: =COUNTA([1]Equalizações!S29:Y29) -> 7 | M27: 45603 | N27: SMI | O27: DAR AGRO | P27: ZAP | Q27: DRW | R27: GTS | S27: NS | T27: MFC (DECLINOU) | V27: DAR AGRO | W27: 564286/564287/564290/564291/564292/564294/564295/564296 | X27: SIM
A28: OK | B28: =IF($X28<>"","Finalizado",IF($O28<>"","Comprador Negociando",IF($M28>=TODAY(),"Aguardando Retorno Fornecedores","Prazo de Retorno Vencido"))) -> Finalizado | C28: =IF(B28="Finalizado","Ok",IF(IF(M28="",_xlfn.DAYS(TODAY(),J28),_xlfn.DAYS(TODAY(),M28))>1,IF(M28="",_xlfn.DAYS(TODAY(),J28),_xlfn.DAYS(TODAY(),M28))&" Dias",IF(M28="",_xlfn.DAYS(TODAY(),J28),_xlfn.DAYS(TODAY(),M28))&" Dia")) -> Ok | D28: 29 | E28: PREVENTIVA DISJUNTORES MEDIA TENSÃO (in loco) | F28: Alta | G28: Eduardo Henrique Silva Souza | H28: APS/Equilibrio/Eletrolucas/ FastDrive | I28: 4 | J28: 45583 | K28: 45590 | L28: =COUNTA([1]Equalizações!S24:Y24) -> 7 | M28: 45602 | N28: EQUILIBRIO | O28: FASTDRIVE | P28: APS | Q28: ELETROLUCAS | V28: ELETROLUCAS | W28: 1125 | X28: SIM
B29: =IF($X29<>"","Finalizado",IF($O29<>"","Comprador Negociando",IF($M29>=TODAY(),"Aguardando Retorno Fornecedores","Prazo de Retorno Vencido"))) -> Finalizado | C29: =IF(B29="Finalizado","Ok",IF(IF(M29="",_xlfn.DAYS(TODAY(),J29),_xlfn.DAYS(TODAY(),M29))>1,IF(M29="",_xlfn.DAYS(TODAY(),J29),_xlfn.DAYS(TODAY(),M29))&" Dias",IF(M29="",_xlfn.DAYS(TODAY(),J29),_xlfn.DAYS(TODAY(),M29))&" Dia")) -> Ok | D29: 33 | E29: Calibração Válvulas de Segurança | F29: Baixa | G29: Igor Marques Assis | H29: Zepponi/Visortech/Valsev/ kcal/Hidrovapor/ Seal Valve/tecnoval | I29: 7 | J29: 45583 | K29: 45590 | L29: =COUNTA([1]Equalizações!S30:Y30) -> 3 | M29: 45603 | N29: KCAL | O29: VALSEV | P29: SEALVALVE | Q29: TECNOVAL | R29: ZEPPONI (NÃO RESPONDEU) | S29: VISORTECH (NÃO RESPONDEU) | T29: HIDROVAPOR (NÃO RESPONDEU) | V29: sealvalve | W29: 564.829/564.831/564.832/564.833/564.834/564.835/564.836/564.837 | X29: SIM
A30: OK | B30: =IF($X30<>"","Finalizado",IF($O30<>"","Comprador Negociando",IF($M30>=TODAY(),"Aguardando Retorno Fornecedores","Prazo de Retorno Vencido"))) -> Finalizado | C30: =IF(B30="Finalizado","Ok",IF(IF(M30="",_xlfn.DAYS(TODAY(),J30),_xlfn.DAYS(TODAY(),M30))>1,IF(M30="",_xlfn.DAYS(TODAY(),J30),_xlfn.DAYS(TODAY(),M30))&" Dias",IF(M30="",_xlfn.DAYS(TODAY(),J30),_xlfn.DAYS(TODAY(),M30))&" Dia")) -> Ok | D30: 28 | E30: PREVENTIVA DISJUNTORES BAIXA TENSÃO (in loco) | F30: Alta | G30: Eduardo Henrique Silva Souza | H30: APS/Equilibrio/Eletrolucas/ Fast Drives | I30: 4 | J30: 45583 | K30: 45590 | L30: =COUNTA([1]Equalizações!S31:Y31) -> 7 | M30: 45603 | N30: FASTDRIVE | O30: APS | P30: ELETROLUCAS | Q30: EQUILIBRIO (NÃO RESPONDEU) | V30: ELETROLUCAS | W30: 1064 | X30: SIM
B31: =IF($X31<>"","Finalizado",IF($O31<>"","Comprador Negociando",IF($M31>=TODAY(),"Aguardando Retorno Fornecedores","Prazo de Retorno Vencido"))) -> Finalizado | C31: =IF(B31="Finalizado","Ok",IF(IF(M31="",_xlfn.DAYS(TODAY(),J31),_xlfn.DAYS(TODAY(),M31))>1,IF(M31="",_xlfn.DAYS(TODAY(),J31),_xlfn.DAYS(TODAY(),M31))&" Dias",IF(M31="",_xlfn.DAYS(TODAY(),J31),_xlfn.DAYS(TODAY(),M31))&" Dia")) -> Ok | D31: 34 | E31: PREVENTIVA TRANSFORMADORES | F31: Alta | G31: Eduardo Henrique Silva Souza | H31: Siner/Prosep/Sercamp/Equilibrio | I31: 4 | J31: 45583 | K31: 45590 | L31: =COUNTA([1]Equalizações!S32:Y32) -> 7 | M31: 45603 | N31: SINER | O31: SERCAMP | P31: PROSEP | Q31: EQUILIBRIO (NÃO RESPONDEU) | V31: SERCAMP | W31: 564816 | X31: SIM
A32: N/A | B32: =IF($X32<>"","Finalizado",IF($O32<>"","Comprador Negociando",IF($M32>=TODAY(),"Aguardando Retorno Fornecedores","Prazo de Retorno Vencido"))) -> Comprador Negociando | C32: =IF(B32="Finalizado","Ok",IF(IF(M32="",_xlfn.DAYS(TODAY(),J32),_xlfn.DAYS(TODAY(),M32))>1,IF(M32="",_xlfn.DAYS(TODAY(),J32),_xlfn.DAYS(TODAY(),M32))&" Dias",IF(M32="",_xlfn.DAYS(TODAY(),J32),_xlfn.DAYS(TODAY(),M32))&" Dia")) -> 559 Dias | D32: 37 | E32: MONTAGEM E FORNECIMENTO DE ANDAIME | F32: Baixa | G32: Eduardo Souza Cunha | H32: Frontal/Monteja | I32: 3 | J32: 45583 | K32: 45590 | L32: =COUNTA([1]Equalizações!S33:Y33) -> 6 | M32: 45603 | N32: FRONTAL | O32: MONTEJA | P32: GRUPO MATOS | V32: MG ANDAIMES | W32: FEITO CONTRATO DE LOCAÇÃO
B33: =IF($X33<>"","Finalizado",IF($O33<>"","Comprador Negociando",IF($M33>=TODAY(),"Aguardando Retorno Fornecedores","Prazo de Retorno Vencido"))) -> Comprador Negociando | C33: =IF(B33="Finalizado","Ok",IF(IF(M33="",_xlfn.DAYS(TODAY(),J33),_xlfn.DAYS(TODAY(),M33))>1,IF(M33="",_xlfn.DAYS(TODAY(),J33),_xlfn.DAYS(TODAY(),M33))&" Dias",IF(M33="",_xlfn.DAYS(TODAY(),J33),_xlfn.DAYS(TODAY(),M33))&" Dia")) -> 558 Dias | D33: 36 | E33: LOCAÇÃO DE GUINDASTES 50 TON | F33: Baixa | G33: Eduardo Souza Cunha | H33: Betel/JAM/Caldemil/Gmig/Gigantão | I33: 5 | J33: 45583 | K33: 45590 | L33: =COUNTA([1]Equalizações!S37:Y37) -> 7 | M33: 45604 | N33: JACOMASSI | O33: GMIG | P33: GIGANTÃO | Q33: CALDEMIL | R33: BETEL | U33: FINALIZADO | V33: CALDEMIL | W33: CONTRATO DE LOCAÇÃO
A34: OK | B34: =IF($X34<>"","Finalizado",IF($O34<>"","Comprador Negociando",IF($M34>=TODAY(),"Aguardando Retorno Fornecedores","Prazo de Retorno Vencido"))) -> Finalizado | C34: =IF(B34="Finalizado","Ok",IF(IF(M34="",_xlfn.DAYS(TODAY(),J34),_xlfn.DAYS(TODAY(),M34))>1,IF(M34="",_xlfn.DAYS(TODAY(),J34),_xlfn.DAYS(TODAY(),M34))&" Dias",IF(M34="",_xlfn.DAYS(TODAY(),J34),_xlfn.DAYS(TODAY(),M34))&" Dia")) -> Ok | D34: 27 | E34: PURGADORES | F34: Baixa | G34: Lucas Henrique Lara Rodrigues | H34: Zepponi/Tecnoval/Kcal/Valsev/HidroVapor | I34: 5 | J34: 45579 | K34: 45593 | L34: =COUNTA([1]Equalizações!S34:Y34) -> 6 | M34: 45603 | N34: ZEPPONI | O34: Kcal | P34: TECNOVAL | Q34: VALSEV | R34: HidroVapor | V34: kcal | W34: 564850/564851/564852/564854/564855/564856/564857/564858/1070 | X34: SIM
A35: OK | B35: =IF($X35<>"","Finalizado",IF($O35<>"","Comprador Negociando",IF($M35>=TODAY(),"Aguardando Retorno Fornecedores","Prazo de Retorno Vencido"))) -> Finalizado | C35: =IF(B35="Finalizado","Ok",IF(IF(M35="",_xlfn.DAYS(TODAY(),J35),_xlfn.DAYS(TODAY(),M35))>1,IF(M35="",_xlfn.DAYS(TODAY(),J35),_xlfn.DAYS(TODAY(),M35))&" Dias",IF(M35="",_xlfn.DAYS(TODAY(),J35),_xlfn.DAYS(TODAY(),M35))&" Dia")) -> Ok | D35: 32 | E35: LIMPEZA A SECO DAS CALDEIRAS 1,2 e 3 | F35: Média | G35: Eduardo Rogerio Maggio | H35: SERVITEC/PROMAC/INDTEC | I35: 3 | J35: 45586 | K35: 45595 | L35: =COUNTA([1]Equalizações!S18:Y18) -> 7 | M35: 45610 | N35: PROMAC (DECLINOU) | O35: INDTEC (DECLINOU) | P35: SERVITEC | U35: Feito Formulario de exclusividade | V35: SERVITEC | W35: 564115/564117/564118 | X35: SIM
B36: =IF($X36<>"","Finalizado",IF($O36<>"","Comprador Negociando",IF($M36>=TODAY(),"Aguardando Retorno Fornecedores","Prazo de Retorno Vencido"))) -> Finalizado | C36: =IF(B36="Finalizado","Ok",IF(IF(M36="",_xlfn.DAYS(TODAY(),J36),_xlfn.DAYS(TODAY(),M36))>1,IF(M36="",_xlfn.DAYS(TODAY(),J36),_xlfn.DAYS(TODAY(),M36))&" Dias",IF(M36="",_xlfn.DAYS(TODAY(),J36),_xlfn.DAYS(TODAY(),M36))&" Dia")) -> Ok | D36: 35 | E36: DESCARREGADORES | F36: Média | G36: Renan Araújo Junqueira Bueno | H36: Ad Service/Ferramaq/Renova/ TJR/Vetek/Vibromaq/Silver | I36: 7 | J36: 45586 | K36: 45595 | L36: =COUNTA([1]Equalizações!S35:Y35) -> 5 | M36: 45603 | N36: VETEK (DECLINOU) | O36: TJR | P36: SILVER WEIBULL | Q36: FERREMAQ | R36: VIBROTEC | S36: RENOVA | T36: AD SERVICE (NÃO RESPONDEU) | V36: RENOVA | W36: 564310/564311 | X36: SIM
B37: =IF($X37<>"","Finalizado",IF($O37<>"","Comprador Negociando",IF($M37>=TODAY(),"Aguardando Retorno Fornecedores","Prazo de Retorno Vencido"))) -> Finalizado | C37: =IF(B37="Finalizado","Ok",IF(IF(M37="",_xlfn.DAYS(TODAY(),J37),_xlfn.DAYS(TODAY(),M37))>1,IF(M37="",_xlfn.DAYS(TODAY(),J37),_xlfn.DAYS(TODAY(),M37))&" Dias",IF(M37="",_xlfn.DAYS(TODAY(),J37),_xlfn.DAYS(TODAY(),M37))&" Dia")) -> Ok | D37: 31 | E37: Pacote Peneira Rotativa Moenda A | F37: Média | G37: Eduardo Rogerio Maggio | H37: VIBROTEC/VIBROMAQ/EQUILIBRIO | I37: 3 | J37: 45586 | K37: 45595 | L37: =COUNTA([1]Equalizações!S38:Y38) -> 6 | M37: 45604 | N37: VIBROTEC | O37: VIBROMAQ (declinou) | P37: EQUILIBRIO | V37: VIBROTEC | W37: 564308/564309/566030 | X37: SIM
A38: OK | B38: =IF($X38<>"","Finalizado",IF($O38<>"","Comprador Negociando",IF($M38>=TODAY(),"Aguardando Retorno Fornecedores","Prazo de Retorno Vencido"))) -> Finalizado | C38: =IF(B38="Finalizado","Ok",IF(IF(M38="",_xlfn.DAYS(TODAY(),J38),_xlfn.DAYS(TODAY(),M38))>1,IF(M38="",_xlfn.DAYS(TODAY(),J38),_xlfn.DAYS(TODAY(),M38))&" Dias",IF(M38="",_xlfn.DAYS(TODAY(),J38),_xlfn.DAYS(TODAY(),M38))&" Dia")) -> Ok | D38: 48 | E38: VALVULAS CORTA CHAMAS | F38: Média | G38: Igor Marques Assis | H38: Zepponi/Tecnoval/Seal Valve | I38: 3 | J38: 45600 | K38: 45600 | L38: =COUNTA([1]Equalizações!S23:Y23) -> 3 | M38: 45600 | N38: zepponi | O38: tecnoval | P38: sealvalve | V38: Zepponi | W38: 564848 | X38: SIM
B39: =IF($X39<>"","Finalizado",IF($O39<>"","Comprador Negociando",IF($M39>=TODAY(),"Aguardando Retorno Fornecedores","Prazo de Retorno Vencido"))) -> Finalizado | C39: =IF(B39="Finalizado","Ok",IF(IF(M39="",_xlfn.DAYS(TODAY(),J39),_xlfn.DAYS(TODAY(),M39))>1,IF(M39="",_xlfn.DAYS(TODAY(),J39),_xlfn.DAYS(TODAY(),M39))&" Dias",IF(M39="",_xlfn.DAYS(TODAY(),J39),_xlfn.DAYS(TODAY(),M39))&" Dia")) -> Ok | D39: 38 | E39: TROCADORES DE CALOR | F39: Alta | G39: Janio Lopes Furtado Junior | H39: Manutrol/Agapito/Rplates/Alfa Laval | I39: 4 | J39: 45593 | K39: 45607 | L39: =COUNTA([1]Equalizações!S41:Y41) -> 3 | M39: 45639 | N39: MANUTROL | O39: Agapito | P39: Rplates | V39: MANUTROL | W39: 564894/564898 | X39: SIM
B40: =IF($X40<>"","Finalizado",IF($O40<>"","Comprador Negociando",IF($M40>=TODAY(),"Aguardando Retorno Fornecedores","Prazo de Retorno Vencido"))) -> Finalizado | C40: =IF(B40="Finalizado","Ok",IF(IF(M40="",_xlfn.DAYS(TODAY(),J40),_xlfn.DAYS(TODAY(),M40))>1,IF(M40="",_xlfn.DAYS(TODAY(),J40),_xlfn.DAYS(TODAY(),M40))&" Dias",IF(M40="",_xlfn.DAYS(TODAY(),J40),_xlfn.DAYS(TODAY(),M40))&" Dia")) -> Ok | D40: 39 | E40: MANUTENÇÃO REDUTORES | F40: Média | G40: Renan Araújo Junqueira Bueno | H40: Wortice/Macopema/ADDN/Cestari | I40: 4 | J40: 45597 | K40: 45607 | L40: =COUNTA([1]Equalizações!S42:Y42) -> 7 | M40: 45635 | N40: CESTARI | O40: MACOPEMA | P40: ADDN | Q40: Wórtice | U40: FORMULÁRIO | V40: CESTARI / MACOPEMA | W40: 565344/565347/565906/565908 | X40: SIM
A41: OK | B41: =IF($X41<>"","Finalizado",IF($O41<>"","Comprador Negociando",IF($M41>=TODAY(),"Aguardando Retorno Fornecedores","Prazo de Retorno Vencido"))) -> Comprador Negociando | C41: =IF(B41="Finalizado","Ok",IF(IF(M41="",_xlfn.DAYS(TODAY(),J41),_xlfn.DAYS(TODAY(),M41))>1,IF(M41="",_xlfn.DAYS(TODAY(),J41),_xlfn.DAYS(TODAY(),M41))&" Dias",IF(M41="",_xlfn.DAYS(TODAY(),J41),_xlfn.DAYS(TODAY(),M41))&" Dia")) -> 527 Dias | D41: 6 | E41: MANUTENÇÃO CENTRIFUGAS DE AÇÚCAR 02 | F41: Baixa | G41: Renan Araújo Junqueira Bueno | H41: Ad Service/Ferramaq/Renova TecSugar/TJR/ Vibromaq/Vibrotec | I41: 7 | J41: 45594 | K41: 45609 | L41: =COUNTA([1]Equalizações!S43:Y43) -> 5 | M41: 45635 | N41: TECSUGAR | O41: FERREMAQ | P41: RENOVA | Q41: VIBROTEC | U41: ESPERANDO PC | V41: VIBROTEC
B42: =IF($X42<>"","Finalizado",IF($O42<>"","Comprador Negociando",IF($M42>=TODAY(),"Aguardando Retorno Fornecedores","Prazo de Retorno Vencido"))) -> Comprador Negociando | C42: =IF(B42="Finalizado","Ok",IF(IF(M42="",_xlfn.DAYS(TODAY(),J42),_xlfn.DAYS(TODAY(),M42))>1,IF(M42="",_xlfn.DAYS(TODAY(),J42),_xlfn.DAYS(TODAY(),M42))&" Dias",IF(M42="",_xlfn.DAYS(TODAY(),J42),_xlfn.DAYS(TODAY(),M42))&" Dia")) -> 559 Dias | D42: 40 | E42: LOCAÇÃO PTAs | F42: Alta | G42: Eduardo Souza Cunha | H42: LOXAM/TECNOGERA/MAKFIL/TRIANGULO | I42: 4 | J42: 45603 | K42: 45616 | L42: =COUNTA([1]Equalizações!S36:Y36) -> 7 | M42: 45603 | N42: LOXAM | O42: TECNOGERA | P42: MAKFIL | Q42: TRIANGULO | V42: makfil | W42: Feito adtivo contrato atual
B43: =IF($X43<>"","Finalizado",IF($O43<>"","Comprador Negociando",IF($M43>=TODAY(),"Aguardando Retorno Fornecedores","Prazo de Retorno Vencido"))) -> Finalizado | C43: =IF(B43="Finalizado","Ok",IF(IF(M43="",_xlfn.DAYS(TODAY(),J43),_xlfn.DAYS(TODAY(),M43))>1,IF(M43="",_xlfn.DAYS(TODAY(),J43),_xlfn.DAYS(TODAY(),M43))&" Dias",IF(M43="",_xlfn.DAYS(TODAY(),J43),_xlfn.DAYS(TODAY(),M43))&" Dia")) -> Ok | D43: 42 | E43: PACOTE CALDEIRARIA SIDERURGICA CALDEIRA 02 | F43: Alta | G43: Eduardo Rogerio Maggio | H43: DAR AGRO/ZAP/NS/MFC/ GTS/BCMAIS/ GRUPOLIMA | I43: 7 | J43: 45608 | K43: 45617 | L43: =COUNTA([1]Equalizações!S44:Y44) -> 6 | M43: 45644 | N43: ZAP | O43: GAMMA (Ag.Email com Garantia) | P43: SB END | V43: SB END/GAMMA | W43: 565319/565320/565321/565322/565324/565325/565326/565327/565328/565330/565333 | X43: SIM
...

Sheet AUX
B3: PLANTA
B4: AUTOMAÇÃO | D4: Responsável
B5: CALDEIRA 01 | D5: Eduardo Henrique Silva Souza
B6: CALDEIRA 02 | D6: Eduardo Souza Cunha
B7: CALDEIRA 03 | D7: Fabio Nunes
B8: CALDEIRARIA | D8: Janio Junior Lopes
B9: CALDEIRAS | D9: Rodrigo Zavatti
B10: CAPTAÇÃO | D10: Thâmara Ceballos
B11: DESTILÁRIA | D11: Bruno Campos
B12: ETA | D12: Leonardo Teixeira
B13: FAB. AÇÚCAR
B14: FABRICA/ARMAZEM
B15: FERMENTAÇÃO
B16: FERMENTAÇÃO/DESTILARIA
B17: GER. ENERGIA
B18: GERAL
B19: INSTRUMENTAÇÃO
B20: LEVEDURA
B21: MECÂNICA
B22: METROLOGIA
B23: MOENDA A
B24: MOENDA B
... B31: VINHAÇA

Sheet Planilha1
